Workbook

Sheet Sheet1
A1: Id | B1: Start time | C1: Completion time | D1: Email | E1: Name | F1: Total points | G1: Quiz feedback | H1: Grade posted time | I1: Points - Current Affective State | J1: Feedback - Current Affective State | K1: Current Affective State . I feel calm | L1: Points - Current Affective State . I feel calm | M1: Feedback - Current Affective State . I feel calm | N1: Current Affective State . I feel tense | O1: Points - Current Affective State . I feel tense | P1: Feedback - Current Affective State . I feel tense | Q1: Current Affective State . I feel relaxed | R1: Points - Current Affective State . I feel relaxed | S1: Feedback - Current Affective State . I feel relaxed | T1: Current Affective State . I feel stressed | U1: Points - Current Affective State . I feel stressed | V1: Feedback - Current Affective State . I feel stressed | W1: Points - Immersive Tendency | X1: Feedback - Immersive Tendency | Y1: Immersive Tendency. I easily become deeply involved in movies or virtual experiences. | Z1: Points - Immersive Tendency. I easily become deeply involved in movies or virtual experiences. | AA1: Feedback - Immersive Tendency. I easily become deeply involved in movies or virtual experiences. | AB1: Immersive Tendency. I am good at blocking out external distractions when focused. | AC1: Points - Immersive Tendency. I am good at blocking out external distractions when focused. | AD1: Feedback - Immersive Tendency. I am good at blocking out external distractions when focused. | AE1: Immersive Tendency. I often lose track of time when engaged in an activity. | AF1: Points - Immersive Tendency. I often lose track of time when engaged in an activity. | AG1: Feedback - Immersive Tendency. I often lose track of time when engaged in an activity. | AH1: Points - Sense of presence and immersion | AI1: Feedback - Sense of presence and immersion | AJ1: Sense of presence and immersion.How much were you able to control the events? | AK1: Points - Sense of presence and immersion.How much were you able to control the events? | AL1: Feedback - Sense of presence and immersion.How much were you able to control the events? | AM1: Sense of presence and immersion.How responsive was the environment to actions that you initiated? | AN1: Points - Sense of presence and immersion.How responsive was the environment to actions that you initiated? | AO1: Feedback - Sense of presence and immersion.How responsive was the environment to actions that you initiated? | AP1: Sense of presence and immersion.How natural did your interactions with the environment seem? | AQ1: Points - Sense of presence and immersion.How natural did your interactions with the environment seem? | AR1: Feedback - Sense of presence and immersion.How natural did your interactions with the environment seem? | AS1: Sense of presence and immersion. How completely were all of your senses engaged? | AT1: Points - Sense of presence and immersion. How completely were all of your senses engaged? | AU1: Feedback - Sense of presence and immersion. How completely were all of your senses engaged? | AV1: Sense of presence and immersion. How much did the visual aspects of the environment involve you? | AW1: Points - Sense of presence and immersion. How much did the visual aspects of the environment involve you? | AX1: Feedback - Sense of presence and immersion. How much did the visual aspects of the environment involve you? | AY1: Sense of presence and immersion. How much did the auditory aspects of the environment involve you? | AZ1: Points - Sense of presence and immersion. How much did the auditory aspects of the environment involve you? | BA1: Feedback - Sense of presence and immersion. How much did the auditory aspects of the environment involve you? | BB1: Sense of presence and immersion. How compelling was your sense of objects moving through space? | BC1: Points - Sense of presence and immersion. How compelling was your sense of objects moving through space? | BD1: Feedback - Sense of presence and immersion. How compelling was your sense of objects moving through space? | BE1: Sense of presence and immersion. How inconsistent or disconnected was the information coming from your various senses? | BF1: Points - Sense of presence and immersion. How inconsistent or disconnected was the information coming from your various senses? | BG1: Feedback - Sense of presence and immersion. How inconsistent or disconnected was the information coming from your various senses? | BH1: Sense of presence and immersion. How much did your experiences in the virtual environment seem consistent with your real-world experiences? | BI1: Points - Sense of presence and immersion. How much did your experiences in the virtual environment seem consistent with your real-world experiences? | BJ1: Feedback - Sense of presence and immersion. How much did your experiences in the virtual environment seem consistent with your real-world experiences? | BK1: Sense of presence and immersion. How compelling was your sense of moving around inside the virtual environment? | BL1: Points - Sense of presence and immersion. How compelling was your sense of moving around inside the virtual environment? | BM1: Feedback - Sense of presence and immersion. How compelling was your sense of moving around inside the virtual environment? | BN1: Sense of presence and immersion. How involved were you in the virtual environment experience? | BO1: Points - Sense of presence and immersion. How involved were you in the virtual environment experience? | BP1: Feedback - Sense of presence and immersion. How involved were you in the virtual environment experience? | BQ1: Sense of presence and immersion. Were you involved in the experience to the extent that you lost track of time? | BR1: Points - Sense of presence and immersion. Were you involved in the experience to the extent that you lost track of time? | BS1: Feedback - Sense of presence and immersion. Were you involved in the experience to the extent that you lost track of time? | BT1: Points - Auditory perception | BU1: Feedback - Auditory perception | BV1: Auditory perception. How well could you identify sounds? | BW1: Points - Auditory perception. How well could you identify sounds? | BX1: Feedback - Auditory perception. How well could you identify sounds? | BY1: Auditory perception. How well could you localize sounds? | BZ1: Points - Auditory perception. How well could you localize sounds? | CA1: Feedback - Auditory perception. How well could you localize sounds? | CB1: Points - Navigation Experience | CC1: Feedback - Navigation Experience | CD1: Navigation Experience. How easy was it to find your way through the environment? | CE1: Points - Navigation Experience. How easy was it to find your way through the environment? | CF1: Feedback - Navigation Experience. How easy was it to find your way through the environment? | CG1: Navigation Experience. How confident did you feel about where you were in the environment at any moment? | CH1: Points - Navigation Experience. How confident did you feel about where you were in the environment at any moment? | CI1: Feedback - Navigation Experience. How confident did you feel about where you were in the environment at any moment? | CJ1: Navigation Experience. To what extent did sounds help you decide where to go next? | CK1: Points - Navigation Experience. To what extent did sounds help you decide where to go next? | CL1: Feedback - Navigation Experience. To what extent did sounds help you decide where to go next? | CM1: Navigation Experience. To what extent did sounds distract you from navigation? | CN1: Points - Navigation Experience. To what extent did sounds distract you from navigation? | CO1: Feedback - Navigation Experience. To what extent did sounds distract you from navigation? | CP1: Points - Post-Experience Affective State | CQ1: Feedback - Post-Experience Affective State | CR1: Post-Experience Affective State . I feel calm | CS1: Points - Post-Experience Affective State . I feel calm | CT1: Feedback - Post-Experience Affective State . I feel calm | CU1: Post-Experience Affective State . I feel tense | CV1: Points - Post-Experience Affective State . I feel tense | CW1: Feedback - Post-Experience Affective State . I feel tense | CX1: Post-Experience Affective State . I feel relaxed | CY1: Points - Post-Experience Affective State . I feel relaxed | CZ1: Feedback - Post-Experience Affective State . I feel relaxed | DA1: Post-Experience Affective State . I feel stressed | DB1: Points - Post-Experience Affective State . I feel stressed | DC1: Feedback - Post-Experience Affective State . I feel stressed | DD1: Points - Physical Comfort | DE1: Feedback - Physical Comfort | DF1: Physical Comfort. I felt disoriented during or after the experience. | DG1: Points - Physical Comfort. I felt disoriented during or after the experience. | DH1: Feedback - Physical Comfort. I felt disoriented during or after the experience. | DI1: Physical Comfort. I felt physically uncomfortable during the experience. | DJ1: Points - Physical Comfort. I felt physically uncomfortable during the experience. | DK1: Feedback - Physical Comfort. I felt physically uncomfortable during the experience.
A2: 1 | B2: 46001.815 | C2: 46001.846 | D2: Congruent_1_1.2 | K2: Considerably / Somewhat agree | L2: =_xlfn.XLOOKUP(K2,Sheet2!$A$1:$A$7,Sheet2!$B$1:$B$7) -> 5 | N2: Not at all / Strongly disagree | O2: =_xlfn.XLOOKUP(N2,Sheet2!$A$1:$A$7,Sheet2!$B$1:$B$7) -> 1 | Q2: Moderately / Neutral | R2: =_xlfn.XLOOKUP(Q2,Sheet2!$A$1:$A$7,Sheet2!$B$1:$B$7) -> 4 | T2: Not at all / Strongly disagree | U2: =_xlfn.XLOOKUP(T2,Sheet2!$A$1:$A$7,Sheet2!$B$1:$B$7) -> 1 | Y2: Very slightly / Disagree | Z2: =_xlfn.XLOOKUP(Y2,Sheet2!$A$1:$A$7,Sheet2!$B$1:$B$7) -> 2 | AB2: Very much / Agree | AC2: =_xlfn.XLOOKUP(AB2,Sheet2!$A$1:$A$7,Sheet2!$B$1:$B$7) -> 6 | AE2: Slightly / Somewhat disagree | AF2: =_xlfn.XLOOKUP(AE2,Sheet2!$A$1:$A$7,Sheet2!$B$1:$B$7) -> 3 | AJ2: Very much / Agree | AK2: =_xlfn.XLOOKUP(AJ2,Sheet2!$A$1:$A$7,Sheet2!$B$1:$B$7) -> 6 | AM2: Considerably / Somewhat agree | AN2: =_xlfn.XLOOKUP(AM2,Sheet2!$A$1:$A$7,Sheet2!$B$1:$B$7) -> 5 | AP2: Considerably / Somewhat agree | AQ2: =_xlfn.XLOOKUP(AP2,Sheet2!$A$1:$A$7,Sheet2!$B$1:$B$7) -> 5 | AS2: Moderately / Neutral | AT2: =_xlfn.XLOOKUP(AS2,Sheet2!$A$1:$A$7,Sheet2!$B$1:$B$7) -> 4 | AV2: Extremely / Strongly agree | AW2: =_xlfn.XLOOKUP(AV2,Sheet2!$A$1:$A$7,Sheet2!$B$1:$B$7) -> 7 | AY2: Moderately / Neutral | AZ2: =_xlfn.XLOOKUP(AY2,Sheet2!$A$1:$A$7,Sheet2!$B$1:$B$7) -> 4 | BB2: Moderately / Neutral | BC2: =_xlfn.XLOOKUP(BB2,Sheet2!$A$1:$A$7,Sheet2!$B$1:$B$7) -> 4 | BE2: Very much / Agree | BF2: =_xlfn.XLOOKUP(BE2,Sheet2!$A$1:$A$7,Sheet2!$B$1:$B$7) -> 6 | BH2: Extremely / Strongly agree | BI2: =_xlfn.XLOOKUP(BH2,Sheet2!$A$1:$A$7,Sheet2!$B$1:$B$7) -> 7 | BK2: Slightly / Somewhat disagree | BL2: =_xlfn.XLOOKUP(BK2,Sheet2!$A$1:$A$7,Sheet2!$B$1:$B$7) -> 3 | BN2: Very slightly / Disagree | BO2: =_xlfn.XLOOKUP(BN2,Sheet2!$A$1:$A$7,Sheet2!$B$1:$B$7) -> 2 | BQ2: Slightly / Somewhat disagree | BR2: =_xlfn.XLOOKUP(BQ2,Sheet2!$A$1:$A$7,Sheet2!$B$1:$B$7) -> 3 | BV2: Considerably / Somewhat agree | BW2: =_xlfn.XLOOKUP(BV2,Sheet2!$A$1:$A$7,Sheet2!$B$1:$B$7) -> 5 | BY2: Slightly / Somewhat disagree | BZ2: =_xlfn.XLOOKUP(BY2,Sheet2!$A$1:$A$7,Sheet2!$B$1:$B$7) -> 3 | CD2: Slightly / Somewhat disagree | CE2: =_xlfn.XLOOKUP(CD2,Sheet2!$A$1:$A$7,Sheet2!$B$1:$B$7) -> 3 | CG2: Very much / Agree | CH2: =_xlfn.XLOOKUP(CG2,Sheet2!$A$1:$A$7,Sheet2!$B$1:$B$7) -> 6 | CJ2: Considerably / Somewhat agree | CK2: =_xlfn.XLOOKUP(CJ2,Sheet2!$A$1:$A$7,Sheet2!$B$1:$B$7) -> 5 | CM2: Very much / Agree | CN2: =_xlfn.XLOOKUP(CM2,Sheet2!$A$1:$A$7,Sheet2!$B$1:$B$7) -> 6 | CR2: Not at all / Strongly disagree | CS2: =_xlfn.XLOOKUP(CR2,Sheet2!$A$1:$A$7,Sheet2!$B$1:$B$7) -> 1 | CU2: Very much / Agree | CV2: =_xlfn.XLOOKUP(CU2,Sheet2!$A$1:$A$7,Sheet2!$B$1:$B$7) -> 6 | CX2: Not at all / Strongly disagree | CY2: =_xlfn.XLOOKUP(CX2,Sheet2!$A$1:$A$7,Sheet2!$B$1:$B$7) -> 1 | DA2: Extremely / Strongly agree | DB2: =_xlfn.XLOOKUP(DA2,Sheet2!$A$1:$A$7,Sheet2!$B$1:$B$7) -> 7 | DF2: Very much / Agree | DG2: =_xlfn.XLOOKUP(DF2,Sheet2!$A$1:$A$7,Sheet2!$B$1:$B$7) -> 6 | DI2: Extremely / Strongly agree | DJ2: =_xlfn.XLOOKUP(DI2,Sheet2!$A$1:$A$7,Sheet2!$B$1:$B$7) -> 7
A3: 2 | B3: 46001.84 | C3: 46001.853 | D3: Incongruent_1 | K3: Very much / Agree | L3: =_xlfn.XLOOKUP(K3,Sheet2!$A$1:$A$7,Sheet2!$B$1:$B$7) -> 6 | N3: Not at all / Strongly disagree | O3: =_xlfn.XLOOKUP(N3,Sheet2!$A$1:$A$7,Sheet2!$B$1:$B$7) -> 1 | Q3: Very much / Agree | R3: =_xlfn.XLOOKUP(Q3,Sheet2!$A$1:$A$7,Sheet2!$B$1:$B$7) -> 6 | T3: Very slightly / Disagree | U3: =_xlfn.XLOOKUP(T3,Sheet2!$A$1:$A$7,Sheet2!$B$1:$B$7) -> 2 | Y3: Moderately / Neutral | Z3: =_xlfn.XLOOKUP(Y3,Sheet2!$A$1:$A$7,Sheet2!$B$1:$B$7) -> 4 | AB3: Very much / Agree | AC3: =_xlfn.XLOOKUP(AB3,Sheet2!$A$1:$A$7,Sheet2!$B$1:$B$7) -> 6 | AE3: Slightly / Somewhat disagree | AF3: =_xlfn.XLOOKUP(AE3,Sheet2!$A$1:$A$7,Sheet2!$B$1:$B$7) -> 3 | AJ3: Slightly / Somewhat disagree | AK3: =_xlfn.XLOOKUP(AJ3,Sheet2!$A$1:$A$7,Sheet2!$B$1:$B$7) -> 3 | AM3: Very slightly / Disagree | AN3: =_xlfn.XLOOKUP(AM3,Sheet2!$A$1:$A$7,Sheet2!$B$1:$B$7) -> 2 | AP3: Slightly / Somewhat disagree | AQ3: =_xlfn.XLOOKUP(AP3,Sheet2!$A$1:$A$7,Sheet2!$B$1:$B$7) -> 3 | AS3: Very much / Agree | AT3: =_xlfn.XLOOKUP(AS3,Sheet2!$A$1:$A$7,Sheet2!$B$1:$B$7) -> 6 | AV3: Moderately / Neutral | AW3: =_xlfn.XLOOKUP(AV3,Sheet2!$A$1:$A$7,Sheet2!$B$1:$B$7) -> 4 | AY3: Very much / Agree | AZ3: =_xlfn.XLOOKUP(AY3,Sheet2!$A$1:$A$7,Sheet2!$B$1:$B$7) -> 6 | BB3: Moderately / Neutral | BC3: =_xlfn.XLOOKUP(BB3,Sheet2!$A$1:$A$7,Sheet2!$B$1:$B$7) -> 4 | BE3: Very slightly / Disagree | BF3: =_xlfn.XLOOKUP(BE3,Sheet2!$A$1:$A$7,Sheet2!$B$1:$B$7) -> 2 | BH3: Slightly / Somewhat disagree | BI3: =_xlfn.XLOOKUP(BH3,Sheet2!$A$1:$A$7,Sheet2!$B$1:$B$7) -> 3 | BK3: Moderately / Neutral | BL3: =_xlfn.XLOOKUP(BK3,Sheet2!$A$1:$A$7,Sheet2!$B$1:$B$7) -> 4 | BN3: Very much / Agree | BO3: =_xlfn.XLOOKUP(BN3,Sheet2!$A$1:$A$7,Sheet2!$B$1:$B$7) -> 6 | BQ3: Very much / Agree | BR3: =_xlfn.XLOOKUP(BQ3,Sheet2!$A$1:$A$7,Sheet2!$B$1:$B$7) -> 6 | BV3: Very much / Agree | BW3: =_xlfn.XLOOKUP(BV3,Sheet2!$A$1:$A$7,Sheet2!$B$1:$B$7) -> 6 | BY3: Very much / Agree | BZ3: =_xlfn.XLOOKUP(BY3,Sheet2!$A$1:$A$7,Sheet2!$B$1:$B$7) -> 6 | CD3: Slightly / Somewhat disagree | CE3: =_xlfn.XLOOKUP(CD3,Sheet2!$A$1:$A$7,Sheet2!$B$1:$B$7) -> 3 | CG3: Slightly / Somewhat disagree | CH3: =_xlfn.XLOOKUP(CG3,Sheet2!$A$1:$A$7,Sheet2!$B$1:$B$7) -> 3 | CJ3: Very much / Agree | CK3: =_xlfn.XLOOKUP(CJ3,Sheet2!$A$1:$A$7,Sheet2!$B$1:$B$7) -> 6 | CM3: Very slightly / Disagree | CN3: =_xlfn.XLOOKUP(CM3,Sheet2!$A$1:$A$7,Sheet2!$B$1:$B$7) -> 2 | CR3: Very slightly / Disagree | CS3: =_xlfn.XLOOKUP(CR3,Sheet2!$A$1:$A$7,Sheet2!$B$1:$B$7) -> 2 | CU3: Very slightly / Disagree | CV3: =_xlfn.XLOOKUP(CU3,Sheet2!$A$1:$A$7,Sheet2!$B$1:$B$7) -> 2 | CX3: Very slightly / Disagree | CY3: =_xlfn.XLOOKUP(CX3,Sheet2!$A$1:$A$7,Sheet2!$B$1:$B$7) -> 2 | DA3: Very much / Agree | DB3: =_xlfn.XLOOKUP(DA3,Sheet2!$A$1:$A$7,Sheet2!$B$1:$B$7) -> 6 | DF3: Not at all / Strongly disagree | DG3: =_xlfn.XLOOKUP(DF3,Sheet2!$A$1:$A$7,Sheet2!$B$1:$B$7) -> 1 | DI3: Considerably / Somewhat agree | DJ3: =_xlfn.XLOOKUP(DI3,Sheet2!$A$1:$A$7,Sheet2!$B$1:$B$7) -> 5
A4: 3 | B4: 46002.426 | C4: 46002.437 | D4: Congruent_2 | K4: Very much / Agree | L4: =_xlfn.XLOOKUP(K4,Sheet2!$A$1:$A$7,Sheet2!$B$1:$B$7) -> 6 | N4: Very slightly / Disagree | O4: =_xlfn.XLOOKUP(N4,Sheet2!$A$1:$A$7,Sheet2!$B$1:$B$7) -> 2 | Q4: Very much / Agree | R4: =_xlfn.XLOOKUP(Q4,Sheet2!$A$1:$A$7,Sheet2!$B$1:$B$7) -> 6 | T4: Very slightly / Disagree | U4: =_xlfn.XLOOKUP(T4,Sheet2!$A$1:$A$7,Sheet2!$B$1:$B$7) -> 2 | Y4: Moderately / Neutral | Z4: =_xlfn.XLOOKUP(Y4,Sheet2!$A$1:$A$7,Sheet2!$B$1:$B$7) -> 4 | AB4: Moderately / Neutral | AC4: =_xlfn.XLOOKUP(AB4,Sheet2!$A$1:$A$7,Sheet2!$B$1:$B$7) -> 4 | AE4: Not at all / Strongly disagree | AF4: =_xlfn.XLOOKUP(AE4,Sheet2!$A$1:$A$7,Sheet2!$B$1:$B$7) -> 1 | AJ4: Very much / Agree | AK4: =_xlfn.XLOOKUP(AJ4,Sheet2!$A$1:$A$7,Sheet2!$B$1:$B$7) -> 6 | AM4: Extremely / Strongly agree | AN4: =_xlfn.XLOOKUP(AM4,Sheet2!$A$1:$A$7,Sheet2!$B$1:$B$7) -> 7 | AP4: Extremely / Strongly agree | AQ4: =_xlfn.XLOOKUP(AP4,Sheet2!$A$1:$A$7,Sheet2!$B$1:$B$7) -> 7 | AS4: Very much / Agree | AT4: =_xlfn.XLOOKUP(AS4,Sheet2!$A$1:$A$7,Sheet2!$B$1:$B$7) -> 6 | AV4: Extremely / Strongly agree | AW4: =_xlfn.XLOOKUP(AV4,Sheet2!$A$1:$A$7,Sheet2!$B$1:$B$7) -> 7 | AY4: Extremely / Strongly agree | AZ4: =_xlfn.XLOOKUP(AY4,Sheet2!$A$1:$A$7,Sheet2!$B$1:$B$7) -> 7 | BB4: Very much / Agree | BC4: =_xlfn.XLOOKUP(BB4,Sheet2!$A$1:$A$7,Sheet2!$B$1:$B$7) -> 6 | BE4: Very slightly / Disagree | BF4: =_xlfn.XLOOKUP(BE4,Sheet2!$A$1:$A$7,Sheet2!$B$1:$B$7) -> 2 | BH4: Very much / Agree | BI4: =_xlfn.XLOOKUP(BH4,Sheet2!$A$1:$A$7,Sheet2!$B$1:$B$7) -> 6 | BK4: Very much / Agree | BL4: =_xlfn.XLOOKUP(BK4,Sheet2!$A$1:$A$7,Sheet2!$B$1:$B$7) -> 6 | BN4: Extremely / Strongly agree | BO4: =_xlfn.XLOOKUP(BN4,Sheet2!$A$1:$A$7,Sheet2!$B$1:$B$7) -> 7 | BQ4: Not at all / Strongly disagree | BR4: =_xlfn.XLOOKUP(BQ4,Sheet2!$A$1:$A$7,Sheet2!$B$1:$B$7) -> 1 | BV4: Extremely / Strongly agree | BW4: =_xlfn.XLOOKUP(BV4,Sheet2!$A$1:$A$7,Sheet2!$B$1:$B$7) -> 7 | BY4: Extremely / Strongly agree | BZ4: =_xlfn.XLOOKUP(BY4,Sheet2!$A$1:$A$7,Sheet2!$B$1:$B$7) -> 7 | CD4: Moderately / Neutral | CE4: =_xlfn.XLOOKUP(CD4,Sheet2!$A$1:$A$7,Sheet2!$B$1:$B$7) -> 4 | CG4: Moderately / Neutral | CH4: =_xlfn.XLOOKUP(CG4,Sheet2!$A$1:$A$7,Sheet2!$B$1:$B$7) -> 4 | CJ4: Extremely / Strongly agree | CK4: =_xlfn.XLOOKUP(CJ4,Sheet2!$A$1:$A$7,Sheet2!$B$1:$B$7) -> 7 | CM4: Not at all / Strongly disagree | CN4: =_xlfn.XLOOKUP(CM4,Sheet2!$A$1:$A$7,Sheet2!$B$1:$B$7) -> 1 | CR4: Considerably / Somewhat agree | CS4: =_xlfn.XLOOKUP(CR4,Sheet2!$A$1:$A$7,Sheet2!$B$1:$B$7) -> 5 | CU4: Moderately / Neutral | CV4: =_xlfn.XLOOKUP(CU4,Sheet2!$A$1:$A$7,Sheet2!$B$1:$B$7) -> 4 | CX4: Slightly / Somewhat disagree | CY4: =_xlfn.XLOOKUP(CX4,Sheet2!$A$1:$A$7,Sheet2!$B$1:$B$7) -> 3 | DA4: Slightly / Somewhat disagree | DB4: =_xlfn.XLOOKUP(DA4,Sheet2!$A$1:$A$7,Sheet2!$B$1:$B$7) -> 3 | DF4: Not at all / Strongly disagree | DG4: =_xlfn.XLOOKUP(DF4,Sheet2!$A$1:$A$7,Sheet2!$B$1:$B$7) -> 1 | DI4: Slightly / Somewhat disagree | DJ4: =_xlfn.XLOOKUP(DI4,Sheet2!$A$1:$A$7,Sheet2!$B$1:$B$7) -> 3
A5: 4 | B5: 46002.456 | C5: 46002.467 | D5: Incongruent_2 | K5: Very much / Agree | L5: =_xlfn.XLOOKUP(K5,Sheet2!$A$1:$A$7,Sheet2!$B$1:$B$7) -> 6 | N5: Very slightly / Disagree | O5: =_xlfn.XLOOKUP(N5,Sheet2!$A$1:$A$7,Sheet2!$B$1:$B$7) -> 2 | Q5: Moderately / Neutral | R5: =_xlfn.XLOOKUP(Q5,Sheet2!$A$1:$A$7,Sheet2!$B$1:$B$7) -> 4 | T5: Very slightly / Disagree | U5: =_xlfn.XLOOKUP(T5,Sheet2!$A$1:$A$7,Sheet2!$B$1:$B$7) -> 2 | Y5: Considerably / Somewhat agree | Z5: =_xlfn.XLOOKUP(Y5,Sheet2!$A$1:$A$7,Sheet2!$B$1:$B$7) -> 5 | AB5: Slightly / Somewhat disagree | AC5: =_xlfn.XLOOKUP(AB5,Sheet2!$A$1:$A$7,Sheet2!$B$1:$B$7) -> 3 | AE5: Extremely / Strongly agree | AF5: =_xlfn.XLOOKUP(AE5,Sheet2!$A$1:$A$7,Sheet2!$B$1:$B$7) -> 7 | AJ5: Moderately / Neutral | AK5: =_xlfn.XLOOKUP(AJ5,Sheet2!$A$1:$A$7,Sheet2!$B$1:$B$7) -> 4 | AM5: Extremely / Strongly agree | AN5: =_xlfn.XLOOKUP(AM5,Sheet2!$A$1:$A$7,Sheet2!$B$1:$B$7) -> 7 | AP5: Extremely / Strongly agree | AQ5: =_xlfn.XLOOKUP(AP5,Sheet2!$A$1:$A$7,Sheet2!$B$1:$B$7) -> 7 | AS5: Extremely / Strongly agree | AT5: =_xlfn.XLOOKUP(AS5,Sheet2!$A$1:$A$7,Sheet2!$B$1:$B$7) -> 7 | AV5: Extremely / Strongly agree | AW5: =_xlfn.XLOOKUP(AV5,Sheet2!$A$1:$A$7,Sheet2!$B$1:$B$7) -> 7 | AY5: Very much / Agree | AZ5: =_xlfn.XLOOKUP(AY5,Sheet2!$A$1:$A$7,Sheet2!$B$1:$B$7) -> 6 | BB5: Extremely / Strongly agree | BC5: =_xlfn.XLOOKUP(BB5,Sheet2!$A$1:$A$7,Sheet2!$B$1:$B$7) -> 7 | BE5: Extremely / Strongly agree | BF5: =_xlfn.XLOOKUP(BE5,Sheet2!$A$1:$A$7,Sheet2!$B$1:$B$7) -> 7 | BH5: Extremely / Strongly agree | BI5: =_xlfn.XLOOKUP(BH5,Sheet2!$A$1:$A$7,Sheet2!$B$1:$B$7) -> 7 | BK5: Extremely / Strongly agree | BL5: =_xlfn.XLOOKUP(BK5,Sheet2!$A$1:$A$7,Sheet2!$B$1:$B$7) -> 7 | BN5: Extremely / Strongly agree | BO5: =_xlfn.XLOOKUP(BN5,Sheet2!$A$1:$A$7,Sheet2!$B$1:$B$7) -> 7 | BQ5: Very much / Agree | BR5: =_xlfn.XLOOKUP(BQ5,Sheet2!$A$1:$A$7,Sheet2!$B$1:$B$7) -> 6 | BV5: Extremely / Strongly agree | BW5: =_xlfn.XLOOKUP(BV5,Sheet2!$A$1:$A$7,Sheet2!$B$1:$B$7) -> 7 | BY5: Extremely / Strongly agree | BZ5: =_xlfn.XLOOKUP(BY5,Sheet2!$A$1:$A$7,Sheet2!$B$1:$B$7) -> 7 | CD5: Considerably / Somewhat agree | CE5: =_xlfn.XLOOKUP(CD5,Sheet2!$A$1:$A$7,Sheet2!$B$1:$B$7) -> 5 | CG5: Extremely / Strongly agree | CH5: =_xlfn.XLOOKUP(CG5,Sheet2!$A$1:$A$7,Sheet2!$B$1:$B$7) -> 7 | CJ5: Considerably / Somewhat agree | CK5: =_xlfn.XLOOKUP(CJ5,Sheet2!$A$1:$A$7,Sheet2!$B$1:$B$7) -> 5 | CM5: Not at all / Strongly disagree | CN5: =_xlfn.XLOOKUP(CM5,Sheet2!$A$1:$A$7,Sheet2!$B$1:$B$7) -> 1 | CR5: Extremely / Strongly agree | CS5: =_xlfn.XLOOKUP(CR5,Sheet2!$A$1:$A$7,Sheet2!$B$1:$B$7) -> 7 | CU5: Not at all / Strongly disagree | CV5: =_xlfn.XLOOKUP(CU5,Sheet2!$A$1:$A$7,Sheet2!$B$1:$B$7) -> 1 | CX5: Very much / Agree | CY5: =_xlfn.XLOOKUP(CX5,Sheet2!$A$1:$A$7,Sheet2!$B$1:$B$7) -> 6 | DA5: Not at all / Strongly disagree | DB5: =_xlfn.XLOOKUP(DA5,Sheet2!$A$1:$A$7,Sheet2!$B$1:$B$7) -> 1 | DF5: Not at all / Strongly disagree | DG5: =_xlfn.XLOOKUP(DF5,Sheet2!$A$1:$A$7,Sheet2!$B$1:$B$7) -> 1 | DI5: Not at all / Strongly disagree | DJ5: =_xlfn.XLOOKUP(DI5,Sheet2!$A$1:$A$7,Sheet2!$B$1:$B$7) -> 1
A6: 5 | B6: 46002.509 | C6: 46002.522 | D6: Congruent_3 | K6: Considerably / Somewhat agree | L6: =_xlfn.XLOOKUP(K6,Sheet2!$A$1:$A$7,Sheet2!$B$1:$B$7) -> 5 | N6: Very slightly / Disagree | O6: =_xlfn.XLOOKUP(N6,Sheet2!$A$1:$A$7,Sheet2!$B$1:$B$7) -> 2 | Q6: Considerably / Somewhat agree | R6: =_xlfn.XLOOKUP(Q6,Sheet2!$A$1:$A$7,Sheet2!$B$1:$B$7) -> 5 | T6: Very slightly / Disagree | U6: =_xlfn.XLOOKUP(T6,Sheet2!$A$1:$A$7,Sheet2!$B$1:$B$7) -> 2 | Y6: Very slightly / Disagree | Z6: =_xlfn.XLOOKUP(Y6,Sheet2!$A$1:$A$7,Sheet2!$B$1:$B$7) -> 2 | AB6: Slightly / Somewhat disagree | AC6: =_xlfn.XLOOKUP(AB6,Sheet2!$A$1:$A$7,Sheet2!$B$1:$B$7) -> 3 | AE6: Very slightly / Disagree | AF6: =_xlfn.XLOOKUP(AE6,Sheet2!$A$1:$A$7,Sheet2!$B$1:$B$7) -> 2 | AJ6: Very much / Agree | AK6: =_xlfn.XLOOKUP(AJ6,Sheet2!$A$1:$A$7,Sheet2!$B$1:$B$7) -> 6 | AM6: Moderately / Neutral | AN6: =_xlfn.XLOOKUP(AM6,Sheet2!$A$1:$A$7,Sheet2!$B$1:$B$7) -> 4 | AP6: Considerably / Somewhat agree | AQ6: =_xlfn.XLOOKUP(AP6,Sheet2!$A$1:$A$7,Sheet2!$B$1:$B$7) -> 5 | AS6: Considerably / Somewhat agree | AT6: =_xlfn.XLOOKUP(AS6,Sheet2!$A$1:$A$7,Sheet2!$B$1:$B$7) -> 5 | AV6: Considerably / Somewhat agree | AW6: =_xlfn.XLOOKUP(AV6,Sheet2!$A$1:$A$7,Sheet2!$B$1:$B$7) -> 5 | AY6: Very much / Agree | AZ6: =_xlfn.XLOOKUP(AY6,Sheet2!$A$1:$A$7,Sheet2!$B$1:$B$7) -> 6 | BB6: Very much / Agree | BC6: =_xlfn.XLOOKUP(BB6,Sheet2!$A$1:$A$7,Sheet2!$B$1:$B$7) -> 6 | BE6: Slightly / Somewhat disagree | BF6: =_xlfn.XLOOKUP(BE6,Sheet2!$A$1:$A$7,Sheet2!$B$1:$B$7) -> 3 | BH6: Considerably / Somewhat agree | BI6: =_xlfn.XLOOKUP(BH6,Sheet2!$A$1:$A$7,Sheet2!$B$1:$B$7) -> 5 | BK6: Considerably / Somewhat agree | BL6: =_xlfn.XLOOKUP(BK6,Sheet2!$A$1:$A$7,Sheet2!$B$1:$B$7) -> 5 | BN6: Considerably / Somewhat agree | BO6: =_xlfn.XLOOKUP(BN6,Sheet2!$A$1:$A$7,Sheet2!$B$1:$B$7) -> 5 | BQ6: Slightly / Somewhat disagree | BR6: =_xlfn.XLOOKUP(BQ6,Sheet2!$A$1:$A$7,Sheet2!$B$1:$B$7) -> 3 | BV6: Very much / Agree | BW6: =_xlfn.XLOOKUP(BV6,Sheet2!$A$1:$A$7,Sheet2!$B$1:$B$7) -> 6 | BY6: Slightly / Somewhat disagree | BZ6: =_xlfn.XLOOKUP(BY6,Sheet2!$A$1:$A$7,Sheet2!$B$1:$B$7) -> 3 | CD6: Considerably / Somewhat agree | CE6: =_xlfn.XLOOKUP(CD6,Sheet2!$A$1:$A$7,Sheet2!$B$1:$B$7) -> 5 | CG6: Considerably / Somewhat agree | CH6: =_xlfn.XLOOKUP(CG6,Sheet2!$A$1:$A$7,Sheet2!$B$1:$B$7) -> 5 | CJ6: Slightly / Somewhat disagree | CK6: =_xlfn.XLOOKUP(CJ6,Sheet2!$A$1:$A$7,Sheet2!$B$1:$B$7) -> 3 | CM6: Not at all / Strongly disagree | CN6: =_xlfn.XLOOKUP(CM6,Sheet2!$A$1:$A$7,Sheet2!$B$1:$B$7) -> 1 | CR6: Moderately / Neutral | CS6: =_xlfn.XLOOKUP(CR6,Sheet2!$A$1:$A$7,Sheet2!$B$1:$B$7) -> 4 | CU6: Slightly / Somewhat disagree | CV6: =_xlfn.XLOOKUP(CU6,Sheet2!$A$1:$A$7,Sheet2!$B$1:$B$7) -> 3 | CX6: Slightly / Somewhat disagree | CY6: =_xlfn.XLOOKUP(CX6,Sheet2!$A$1:$A$7,Sheet2!$B$1:$B$7) -> 3 | DA6: Slightly / Somewhat disagree | DB6: =_xlfn.XLOOKUP(DA6,Sheet2!$A$1:$A$7,Sheet2!$B$1:$B$7) -> 3 | DF6: Considerably / Somewhat agree | DG6: =_xlfn.XLOOKUP(DF6,Sheet2!$A$1:$A$7,Sheet2!$B$1:$B$7) -> 5 | DI6: Not at all / Strongly disagree | DJ6: =_xlfn.XLOOKUP(DI6,Sheet2!$A$1:$A$7,Sheet2!$B$1:$B$7) -> 1
A7: 6 | B7: 46002.603 | C7: 46002.613 | D7: Incongruent_3 | K7: Moderately / Neutral | L7: =_xlfn.XLOOKUP(K7,Sheet2!$A$1:$A$7,Sheet2!$B$1:$B$7) -> 4 | N7: Considerably / Somewhat agree | O7: =_xlfn.XLOOKUP(N7,Sheet2!$A$1:$A$7,Sheet2!$B$1:$B$7) -> 5 | Q7: Slightly / Somewhat disagree | R7: =_xlfn.XLOOKUP(Q7,Sheet2!$A$1:$A$7,Sheet2!$B$1:$B$7) -> 3 | T7: Considerably / Somewhat agree | U7: =_xlfn.XLOOKUP(T7,Sheet2!$A$1:$A$7,Sheet2!$B$1:$B$7) -> 5 | Y7: Very much / Agree | Z7: =_xlfn.XLOOKUP(Y7,Sheet2!$A$1:$A$7,Sheet2!$B$1:$B$7) -> 6 | AB7: Very much / Agree | AC7: =_xlfn.XLOOKUP(AB7,Sheet2!$A$1:$A$7,Sheet2!$B$1:$B$7) -> 6 | AE7: Slightly / Somewhat disagree | AF7: =_xlfn.XLOOKUP(AE7,Sheet2!$A$1:$A$7,Sheet2!$B$1:$B$7) -> 3 | AJ7: Very much / Agree | AK7: =_xlfn.XLOOKUP(AJ7,Sheet2!$A$1:$A$7,Sheet2!$B$1:$B$7) -> 6 | AM7: Very much / Agree | AN7: =_xlfn.XLOOKUP(AM7,Sheet2!$A$1:$A$7,Sheet2!$B$1:$B$7) -> 6 | AP7: Considerably / Somewhat agree | AQ7: =_xlfn.XLOOKUP(AP7,Sheet2!$A$1:$A$7,Sheet2!$B$1:$B$7) -> 5 | AS7: Considerably / Somewhat agree | AT7: =_xlfn.XLOOKUP(AS7,Sheet2!$A$1:$A$7,Sheet2!$B$1:$B$7) -> 5 | AV7: Considerably / Somewhat agree | AW7: =_xlfn.XLOOKUP(AV7,Sheet2!$A$1:$A$7,Sheet2!$B$1:$B$7) -> 5 | AY7: Considerably / Somewhat agree | AZ7: =_xlfn.XLOOKUP(AY7,Sheet2!$A$1:$A$7,Sheet2!$B$1:$B$7) -> 5 | BB7: Very much / Agree | BC7: =_xlfn.XLOOKUP(BB7,Sheet2!$A$1:$A$7,Sheet2!$B$1:$B$7) -> 6 | BE7: Moderately / Neutral | BF7: =_xlfn.XLOOKUP(BE7,Sheet2!$A$1:$A$7,Sheet2!$B$1:$B$7) -> 4 | BH7: Considerably / Somewhat agree | BI7: =_xlfn.XLOOKUP(BH7,Sheet2!$A$1:$A$7,Sheet2!$B$1:$B$7) -> 5 | BK7: Considerably / Somewhat agree | BL7: =_xlfn.XLOOKUP(BK7,Sheet2!$A$1:$A$7,Sheet2!$B$1:$B$7) -> 5 | BN7: Very much / Agree | BO7: =_xlfn.XLOOKUP(BN7,Sheet2!$A$1:$A$7,Sheet2!$B$1:$B$7) -> 6 | BQ7: Moderately / Neutral | BR7: =_xlfn.XLOOKUP(BQ7,Sheet2!$A$1:$A$7,Sheet2!$B$1:$B$7) -> 4 | BV7: Very much / Agree | BW7: =_xlfn.XLOOKUP(BV7,Sheet2!$A$1:$A$7,Sheet2!$B$1:$B$7) -> 6 | BY7: Moderately / Neutral | BZ7: =_xlfn.XLOOKUP(BY7,Sheet2!$A$1:$A$7,Sheet2!$B$1:$B$7) -> 4 | CD7: Considerably / Somewhat agree | CE7: =_xlfn.XLOOKUP(CD7,Sheet2!$A$1:$A$7,Sheet2!$B$1:$B$7) -> 5 | CG7: Moderately / Neutral | CH7: =_xlfn.XLOOKUP(CG7,Sheet2!$A$1:$A$7,Sheet2!$B$1:$B$7) -> 4 | CJ7: Moderately / Neutral | CK7: =_xlfn.XLOOKUP(CJ7,Sheet2!$A$1:$A$7,Sheet2!$B$1:$B$7) -> 4 | CM7: Slightly / Somewhat disagree | CN7: =_xlfn.XLOOKUP(CM7,Sheet2!$A$1:$A$7,Sheet2!$B$1:$B$7) -> 3 | CR7: Not at all / Strongly disagree | CS7: =_xlfn.XLOOKUP(CR7,Sheet2!$A$1:$A$7,Sheet2!$B$1:$B$7) -> 1 | CU7: Very much / Agree | CV7: =_xlfn.XLOOKUP(CU7,Sheet2!$A$1:$A$7,Sheet2!$B$1:$B$7) -> 6 | CX7: Not at all / Strongly disagree | CY7: =_xlfn.XLOOKUP(CX7,Sheet2!$A$1:$A$7,Sheet2!$B$1:$B$7) -> 1 | DA7: Very much / Agree | DB7: =_xlfn.XLOOKUP(DA7,Sheet2!$A$1:$A$7,Sheet2!$B$1:$B$7) -> 6 | DF7: Extremely / Strongly agree | DG7: =_xlfn.XLOOKUP(DF7,Sheet2!$A$1:$A$7,Sheet2!$B$1:$B$7) -> 7 | DI7: Extremely / Strongly agree | DJ7: =_xlfn.XLOOKUP(DI7,Sheet2!$A$1:$A$7,Sheet2!$B$1:$B$7) -> 7
A8: 7 | B8: 46002.656 | C8: 46002.681 | D8: Incongruent_4 | K8: Slightly / Somewhat disagree | L8: =_xlfn.XLOOKUP(K8,Sheet2!$A$1:$A$7,Sheet2!$B$1:$B$7) -> 3 | N8: Very much / Agree | O8: =_xlfn.XLOOKUP(N8,Sheet2!$A$1:$A$7,Sheet2!$B$1:$B$7) -> 6 | Q8: Moderately / Neutral | R8: =_xlfn.XLOOKUP(Q8,Sheet2!$A$1:$A$7,Sheet2!$B$1:$B$7) -> 4 | T8: Considerably / Somewhat agree | U8: =_xlfn.XLOOKUP(T8,Sheet2!$A$1:$A$7,Sheet2!$B$1:$B$7) -> 5 | Y8: Extremely / Strongly agree | Z8: =_xlfn.XLOOKUP(Y8,Sheet2!$A$1:$A$7,Sheet2!$B$1:$B$7) -> 7 | AB8: Extremely / Strongly agree | AC8: =_xlfn.XLOOKUP(AB8,Sheet2!$A$1:$A$7,Sheet2!$B$1:$B$7) -> 7 | AE8: Extremely / Strongly agree | AF8: =_xlfn.XLOOKUP(AE8,Sheet2!$A$1:$A$7,Sheet2!$B$1:$B$7) -> 7 | AJ8: Moderately / Neutral | AK8: =_xlfn.XLOOKUP(AJ8,Sheet2!$A$1:$A$7,Sheet2!$B$1:$B$7) -> 4 | AM8: Slightly / Somewhat disagree | AN8: =_xlfn.XLOOKUP(AM8,Sheet2!$A$1:$A$7,Sheet2!$B$1:$B$7) -> 3 | AP8: Considerably / Somewhat agree | AQ8: =_xlfn.XLOOKUP(AP8,Sheet2!$A$1:$A$7,Sheet2!$B$1:$B$7) -> 5 | AS8: Very much / Agree | AT8: =_xlfn.XLOOKUP(AS8,Sheet2!$A$1:$A$7,Sheet2!$B$1:$B$7) -> 6 | AV8: Very much / Agree | AW8: =_xlfn.XLOOKUP(AV8,Sheet2!$A$1:$A$7,Sheet2!$B$1:$B$7) -> 6 | AY8: Very much / Agree | AZ8: =_xlfn.XLOOKUP(AY8,Sheet2!$A$1:$A$7,Sheet2!$B$1:$B$7) -> 6 | BB8: Very much / Agree | BC8: =_xlfn.XLOOKUP(BB8,Sheet2!$A$1:$A$7,Sheet2!$B$1:$B$7) -> 6 | BE8: Extremely / Strongly agree | BF8: =_xlfn.XLOOKUP(BE8,Sheet2!$A$1:$A$7,Sheet2!$B$1:$B$7) -> 7 | BH8: Very slightly / Disagree | BI8: =_xlfn.XLOOKUP(BH8,Sheet2!$A$1:$A$7,Sheet2!$B$1:$B$7) -> 2 | BK8: Very much / Agree | BL8: =_xlfn.XLOOKUP(BK8,Sheet2!$A$1:$A$7,Sheet2!$B$1:$B$7) -> 6 | BN8: Extremely / Strongly agree | BO8: =_xlfn.XLOOKUP(BN8,Sheet2!$A$1:$A$7,Sheet2!$B$1:$B$7) -> 7 | BQ8: Very much / Agree | BR8: =_xlfn.XLOOKUP(BQ8,Sheet2!$A$1:$A$7,Sheet2!$B$1:$B$7) -> 6 | BV8: Very much / Agree | BW8: =_xlfn.XLOOKUP(BV8,Sheet2!$A$1:$A$7,Sheet2!$B$1:$B$7) -> 6 | BY8: Extremely / Strongly agree | BZ8: =_xlfn.XLOOKUP(BY8,Sheet2!$A$1:$A$7,Sheet2!$B$1:$B$7) -> 7 | CD8: Slightly / Somewhat disagree | CE8: =_xlfn.XLOOKUP(CD8,Sheet2!$A$1:$A$7,Sheet2!$B$1:$B$7) -> 3 | CG8: Considerably / Somewhat agree | CH8: =_xlfn.XLOOKUP(CG8,Sheet2!$A$1:$A$7,Sheet2!$B$1:$B$7) -> 5 | CJ8: Very much / Agree | CK8: =_xlfn.XLOOKUP(CJ8,Sheet2!$A$1:$A$7,Sheet2!$B$1:$B$7) -> 6 | CM8: Not at all / Strongly disagree | CN8: =_xlfn.XLOOKUP(CM8,Sheet2!$A$1:$A$7,Sheet2!$B$1:$B$7) -> 1 | CR8: Very slightly / Disagree | CS8: =_xlfn.XLOOKUP(CR8,Sheet2!$A$1:$A$7,Sheet2!$B$1:$B$7) -> 2 | CU8: Considerably / Somewhat agree | CV8: =_xlfn.XLOOKUP(CU8,Sheet2!$A$1:$A$7,Sheet2!$B$1:$B$7) -> 5 | CX8: Slightly / Somewhat disagree | CY8: =_xlfn.XLOOKUP(CX8,Sheet2!$A$1:$A$7,Sheet2!$B$1:$B$7) -> 3 | DA8: Considerably / Somewhat agree | DB8: =_xlfn.XLOOKUP(DA8,Sheet2!$A$1:$A$7,Sheet2!$B$1:$B$7) -> 5 | DF8: Not at all / Strongly disagree | DG8: =_xlfn.XLOOKUP(DF8,Sheet2!$A$1:$A$7,Sheet2!$B$1:$B$7) -> 1 | DI8: Very slightly / Disagree | DJ8: =_xlfn.XLOOKUP(DI8,Sheet2!$A$1:$A$7,Sheet2!$B$1:$B$7) -> 2
A9: 8 | B9: 46002.756 | C9: 46002.767 | D9: Congruent_4 | K9: Extremely / Strongly agree | L9: =_xlfn.XLOOKUP(K9,Sheet2!$A$1:$A$7,Sheet2!$B$1:$B$7) -> 7 | N9: Not at all / Strongly disagree | O9: =_xlfn.XLOOKUP(N9,Sheet2!$A$1:$A$7,Sheet2!$B$1:$B$7) -> 1 | Q9: Extremely / Strongly agree | R9: =_xlfn.XLOOKUP(Q9,Sheet2!$A$1:$A$7,Sheet2!$B$1:$B$7) -> 7 | T9: Not at all / Strongly disagree | U9: =_xlfn.XLOOKUP(T9,Sheet2!$A$1:$A$7,Sheet2!$B$1:$B$7) -> 1 | Y9: Very much / Agree | Z9: =_xlfn.XLOOKUP(Y9,Sheet2!$A$1:$A$7,Sheet2!$B$1:$B$7) -> 6 | AB9: Very much / Agree | AC9: =_xlfn.XLOOKUP(AB9,Sheet2!$A$1:$A$7,Sheet2!$B$1:$B$7) -> 6 | AE9: Very much / Agree | AF9: =_xlfn.XLOOKUP(AE9,Sheet2!$A$1:$A$7,Sheet2!$B$1:$B$7) -> 6 | AJ9: Very much / Agree | AK9: =_xlfn.XLOOKUP(AJ9,Sheet2!$A$1:$A$7,Sheet2!$B$1:$B$7) -> 6 | AM9: Very much / Agree | AN9: =_xlfn.XLOOKUP(AM9,Sheet2!$A$1:$A$7,Sheet2!$B$1:$B$7) -> 6 | AP9: Considerably / Somewhat agree | AQ9: =_xlfn.XLOOKUP(AP9,Sheet2!$A$1:$A$7,Sheet2!$B$1:$B$7) -> 5 | AS9: Extremely / Strongly agree | AT9: =_xlfn.XLOOKUP(AS9,Sheet2!$A$1:$A$7,Sheet2!$B$1:$B$7) -> 7 | AV9: Very much / Agree | AW9: =_xlfn.XLOOKUP(AV9,Sheet2!$A$1:$A$7,Sheet2!$B$1:$B$7) -> 6 | AY9: Very much / Agree | AZ9: =_xlfn.XLOOKUP(AY9,Sheet2!$A$1:$A$7,Sheet2!$B$1:$B$7) -> 6 | BB9: Moderately / Neutral | BC9: =_xlfn.XLOOKUP(BB9,Sheet2!$A$1:$A$7,Sheet2!$B$1:$B$7) -> 4 | BE9: Not at all / Strongly disagree | BF9: =_xlfn.XLOOKUP(BE9,Sheet2!$A$1:$A$7,Sheet2!$B$1:$B$7) -> 1 | BH9: Considerably / Somewhat agree | BI9: =_xlfn.XLOOKUP(BH9,Sheet2!$A$1:$A$7,Sheet2!$B$1:$B$7) -> 5 | BK9: Very much / Agree | BL9: =_xlfn.XLOOKUP(BK9,Sheet2!$A$1:$A$7,Sheet2!$B$1:$B$7) -> 6 | BN9: Very much / Agree | BO9: =_xlfn.XLOOKUP(BN9,Sheet2!$A$1:$A$7,Sheet2!$B$1:$B$7) -> 6 | BQ9: Extremely / Strongly agree | BR9: =_xlfn.XLOOKUP(BQ9,Sheet2!$A$1:$A$7,Sheet2!$B$1:$B$7) -> 7 | BV9: Extremely / Strongly agree | BW9: =_xlfn.XLOOKUP(BV9,Sheet2!$A$1:$A$7,Sheet2!$B$1:$B$7) -> 7 | BY9: Considerably / Somewhat agree | BZ9: =_xlfn.XLOOKUP(BY9,Sheet2!$A$1:$A$7,Sheet2!$B$1:$B$7) -> 5 | CD9: Very much / Agree | CE9: =_xlfn.XLOOKUP(CD9,Sheet2!$A$1:$A$7,Sheet2!$B$1:$B$7) -> 6 | CG9: Extremely / Strongly agree | CH9: =_xlfn.XLOOKUP(CG9,Sheet2!$A$1:$A$7,Sheet2!$B$1:$B$7) -> 7 | CJ9: Extremely / Strongly agree | CK9: =_xlfn.XLOOKUP(CJ9,Sheet2!$A$1:$A$7,Sheet2!$B$1:$B$7) -> 7 | CM9: Not at all / Strongly disagree | CN9: =_xlfn.XLOOKUP(CM9,Sheet2!$A$1:$A$7,Sheet2!$B$1:$B$7) -> 1 | CR9: Very much / Agree | CS9: =_xlfn.XLOOKUP(CR9,Sheet2!$A$1:$A$7,Sheet2!$B$1:$B$7) -> 6 | CU9: Very much / Agree | CV9: =_xlfn.XLOOKUP(CU9,Sheet2!$A$1:$A$7,Sheet2!$B$1:$B$7) -> 6 | CX9: Extremely / Strongly agree | CY9: =_xlfn.XLOOKUP(CX9,Sheet2!$A$1:$A$7,Sheet2!$B$1:$B$7) -> 7 | DA9: Not at all / Strongly disagree | DB9: =_xlfn.XLOOKUP(DA9,Sheet2!$A$1:$A$7,Sheet2!$B$1:$B$7) -> 1 | DF9: Very slightly / Disagree | DG9: =_xlfn.XLOOKUP(DF9,Sheet2!$A$1:$A$7,Sheet2!$B$1:$B$7) -> 2 | DI9: Not at all / Strongly disagree | DJ9: =_xlfn.XLOOKUP(DI9,Sheet2!$A$1:$A$7,Sheet2!$B$1:$B$7) -> 1
A10: 9 | B10: 46003.445 | C10: 46003.454 | D10: Incongruent_5 | K10: Very much / Agree | L10: =_xlfn.XLOOKUP(K10,Sheet2!$A$1:$A$7,Sheet2!$B$1:$B$7) -> 6 | N10: Very slightly / Disagree | O10: =_xlfn.XLOOKUP(N10,Sheet2!$A$1:$A$7,Sheet2!$B$1:$B$7) -> 2 | Q10: Very much / Agree | R10: =_xlfn.XLOOKUP(Q10,Sheet2!$A$1:$A$7,Sheet2!$B$1:$B$7) -> 6 | T10: Not at all / Strongly disagree | U10: =_xlfn.XLOOKUP(T10,Sheet2!$A$1:$A$7,Sheet2!$B$1:$B$7) -> 1 | Y10: Considerably / Somewhat agree | Z10: =_xlfn.XLOOKUP(Y10,Sheet2!$A$1:$A$7,Sheet2!$B$1:$B$7) -> 5 | AB10: Considerably / Somewhat agree | AC10: =_xlfn.XLOOKUP(AB10,Sheet2!$A$1:$A$7,Sheet2!$B$1:$B$7) -> 5 | AE10: Very much / Agree | AF10: =_xlfn.XLOOKUP(AE10,Sheet2!$A$1:$A$7,Sheet2!$B$1:$B$7) -> 6 | AJ10: Very much / Agree | AK10: =_xlfn.XLOOKUP(AJ10,Sheet2!$A$1:$A$7,Sheet2!$B$1:$B$7) -> 6 | AM10: Considerably / Somewhat agree | AN10: =_xlfn.XLOOKUP(AM10,Sheet2!$A$1:$A$7,Sheet2!$B$1:$B$7) -> 5 | AP10: Moderately / Neutral | AQ10: =_xlfn.XLOOKUP(AP10,Sheet2!$A$1:$A$7,Sheet2!$B$1:$B$7) -> 4 | AS10: Considerably / Somewhat agree | AT10: =_xlfn.XLOOKUP(AS10,Sheet2!$A$1:$A$7,Sheet2!$B$1:$B$7) -> 5 | AV10: Considerably / Somewhat agree | AW10: =_xlfn.XLOOKUP(AV10,Sheet2!$A$1:$A$7,Sheet2!$B$1:$B$7) -> 5 | AY10: Moderately / Neutral | AZ10: =_xlfn.XLOOKUP(AY10,Sheet2!$A$1:$A$7,Sheet2!$B$1:$B$7) -> 4 | BB10: Considerably / Somewhat agree | BC10: =_xlfn.XLOOKUP(BB10,Sheet2!$A$1:$A$7,Sheet2!$B$1:$B$7) -> 5 | BE10: Moderately / Neutral | BF10: =_xlfn.XLOOKUP(BE10,Sheet2!$A$1:$A$7,Sheet2!$B$1:$B$7) -> 4 | BH10: Moderately / Neutral | BI10: =_xlfn.XLOOKUP(BH10,Sheet2!$A$1:$A$7,Sheet2!$B$1:$B$7) -> 4 | BK10: Considerably / Somewhat agree | BL10: =_xlfn.XLOOKUP(BK10,Sheet2!$A$1:$A$7,Sheet2!$B$1:$B$7) -> 5 | BN10: Considerably / Somewhat agree | BO10: =_xlfn.XLOOKUP(BN10,Sheet2!$A$1:$A$7,Sheet2!$B$1:$B$7) -> 5 | BQ10: Moderately / Neutral | BR10: =_xlfn.XLOOKUP(BQ10,Sheet2!$A$1:$A$7,Sheet2!$B$1:$B$7) -> 4 | BV10: Very much / Agree | BW10: =_xlfn.XLOOKUP(BV10,Sheet2!$A$1:$A$7,Sheet2!$B$1:$B$7) -> 6 | BY10: Very much / Agree | BZ10: =_xlfn.XLOOKUP(BY10,Sheet2!$A$1:$A$7,Sheet2!$B$1:$B$7) -> 6 | CD10: Moderately / Neutral | CE10: =_xlfn.XLOOKUP(CD10,Sheet2!$A$1:$A$7,Sheet2!$B$1:$B$7) -> 4 | CG10: Considerably / Somewhat agree | CH10: =_xlfn.XLOOKUP(CG10,Sheet2!$A$1:$A$7,Sheet2!$B$1:$B$7) -> 5 | CJ10: Very much / Agree | CK10: =_xlfn.XLOOKUP(CJ10,Sheet2!$A$1:$A$7,Sheet2!$B$1:$B$7) -> 6 | CM10: Extremely / Strongly agree | CN10: =_xlfn.XLOOKUP(CM10,Sheet2!$A$1:$A$7,Sheet2!$B$1:$B$7) -> 7 | CR10: Very much / Agree | CS10: =_xlfn.XLOOKUP(CR10,Sheet2!$A$1:$A$7,Sheet2!$B$1:$B$7) -> 6 | CU10: Slightly / Somewhat disagree | CV10: =_xlfn.XLOOKUP(CU10,Sheet2!$A$1:$A$7,Sheet2!$B$1:$B$7) -> 3 | CX10: Moderately / Neutral | CY10: =_xlfn.XLOOKUP(CX10,Sheet2!$A$1:$A$7,Sheet2!$B$1:$B$7) -> 4 | DA10: Slightly / Somewhat disagree | DB10: =_xlfn.XLOOKUP(DA10,Sheet2!$A$1:$A$7,Sheet2!$B$1:$B$7) -> 3 | DF10: Considerably / Somewhat agree | DG10: =_xlfn.XLOOKUP(DF10,Sheet2!$A$1:$A$7,Sheet2!$B$1:$B$7) -> 5 | DI10: Very slightly / Disagree | DJ10: =_xlfn.XLOOKUP(DI10,Sheet2!$A$1:$A$7,Sheet2!$B$1:$B$7) -> 2
A11: 10 | B11: 46003.729 | C11: 46003.743 | D11: Incongruent_6 | K11: Very much / Agree | L11: =_xlfn.XLOOKUP(K11,Sheet2!$A$1:$A$7,Sheet2!$B$1:$B$7) -> 6 | N11: Very slightly / Disagree | O11: =_xlfn.XLOOKUP(N11,Sheet2!$A$1:$A$7,Sheet2!$B$1:$B$7) -> 2 | Q11: Very much / Agree | R11: =_xlfn.XLOOKUP(Q11,Sheet2!$A$1:$A$7,Sheet2!$B$1:$B$7) -> 6 | T11: Very slightly / Disagree | U11: =_xlfn.XLOOKUP(T11,Sheet2!$A$1:$A$7,Sheet2!$B$1:$B$7) -> 2 | Y11: Very much / Agree | Z11: =_xlfn.XLOOKUP(Y11,Sheet2!$A$1:$A$7,Sheet2!$B$1:$B$7) -> 6 | AB11: Very much / Agree | AC11: =_xlfn.XLOOKUP(AB11,Sheet2!$A$1:$A$7,Sheet2!$B$1:$B$7) -> 6 | AE11: Considerably / Somewhat agree | AF11: =_xlfn.XLOOKUP(AE11,Sheet2!$A$1:$A$7,Sheet2!$B$1:$B$7) -> 5 | AJ11: Considerably / Somewhat agree | AK11: =_xlfn.XLOOKUP(AJ11,Sheet2!$A$1:$A$7,Sheet2!$B$1:$B$7) -> 5 | AM11: Very much / Agree | AN11: =_xlfn.XLOOKUP(AM11,Sheet2!$A$1:$A$7,Sheet2!$B$1:$B$7) -> 6 | AP11: Very much / Agree | AQ11: =_xlfn.XLOOKUP(AP11,Sheet2!$A$1:$A$7,Sheet2!$B$1:$B$7) -> 6 | AS11: Considerably / Somewhat agree | AT11: =_xlfn.XLOOKUP(AS11,Sheet2!$A$1:$A$7,Sheet2!$B$1:$B$7) -> 5 | AV11: Extremely / Strongly agree | AW11: =_xlfn.XLOOKUP(AV11,Sheet2!$A$1:$A$7,Sheet2!$B$1:$B$7) -> 7 | AY11: Extremely / Strongly agree | AZ11: =_xlfn.XLOOKUP(AY11,Sheet2!$A$1:$A$7,Sheet2!$B$1:$B$7) -> 7 | BB11: Very much / Agree | BC11: =_xlfn.XLOOKUP(BB11,Sheet2!$A$1:$A$7,Sheet2!$B$1:$B$7) -> 6 | BE11: Very slightly / Disagree | BF11: =_xlfn.XLOOKUP(BE11,Sheet2!$A$1:$A$7,Sheet2!$B$1:$B$7) -> 2 | BH11: Moderately / Neutral | BI11: =_xlfn.XLOOKUP(BH11,Sheet2!$A$1:$A$7,Sheet2!$B$1:$B$7) -> 4 | BK11: Moderately / Neutral | BL11: =_xlfn.XLOOKUP(BK11,Sheet2!$A$1:$A$7,Sheet2!$B$1:$B$7) -> 4 | BN11: Very much / Agree | BO11: =_xlfn.XLOOKUP(BN11,Sheet2!$A$1:$A$7,Sheet2!$B$1:$B$7) -> 6 | BQ11: Considerably / Somewhat agree | BR11: =_xlfn.XLOOKUP(BQ11,Sheet2!$A$1:$A$7,Sheet2!$B$1:$B$7) -> 5 | BV11: Extremely / Strongly agree | BW11: =_xlfn.XLOOKUP(BV11,Sheet2!$A$1:$A$7,Sheet2!$B$1:$B$7) -> 7 | BY11: Extremely / Strongly agree | BZ11: =_xlfn.XLOOKUP(BY11,Sheet2!$A$1:$A$7,Sheet2!$B$1:$B$7) -> 7 | CD11: Considerably / Somewhat agree | CE11: =_xlfn.XLOOKUP(CD11,Sheet2!$A$1:$A$7,Sheet2!$B$1:$B$7) -> 5 | CG11: Considerably / Somewhat agree | CH11: =_xlfn.XLOOKUP(CG11,Sheet2!$A$1:$A$7,Sheet2!$B$1:$B$7) -> 5 | CJ11: Very much / Agree | CK11: =_xlfn.XLOOKUP(CJ11,Sheet2!$A$1:$A$7,Sheet2!$B$1:$B$7) -> 6 | CM11: Very slightly / Disagree | CN11: =_xlfn.XLOOKUP(CM11,Sheet2!$A$1:$A$7,Sheet2!$B$1:$B$7) -> 2 | CR11: Moderately / Neutral | CS11: =_xlfn.XLOOKUP(CR11,Sheet2!$A$1:$A$7,Sheet2!$B$1:$B$7) -> 4 | CU11: Very slightly / Disagree | CV11: =_xlfn.XLOOKUP(CU11,Sheet2!$A$1:$A$7,Sheet2!$B$1:$B$7) -> 2 | CX11: Moderately / Neutral | CY11: =_xlfn.XLOOKUP(CX11,Sheet2!$A$1:$A$7,Sheet2!$B$1:$B$7) -> 4 | DA11: Very slightly / Disagree | DB11: =_xlfn.XLOOKUP(DA11,Sheet2!$A$1:$A$7,Sheet2!$B$1:$B$7) -> 2 | DF11: Considerably / Somewhat agree | DG11: =_xlfn.XLOOKUP(DF11,Sheet2!$A$1:$A$7,Sheet2!$B$1:$B$7) -> 5 | DI11: Considerably / Somewhat agree | DJ11: =_xlfn.XLOOKUP(DI11,Sheet2!$A$1:$A$7,Sheet2!$B$1:$B$7) -> 5
A12: 11 | B12: 46003.78 | C12: 46003.792 | D12: Congruent_5 | K12: Moderately / Neutral | L12: =_xlfn.XLOOKUP(K12,Sheet2!$A$1:$A$7,Sheet2!$B$1:$B$7) -> 4 | N12: Moderately / Neutral | O12: =_xlfn.XLOOKUP(N12,Sheet2!$A$1:$A$7,Sheet2!$B$1:$B$7) -> 4 | Q12: Slightly / Somewhat disagree | R12: =_xlfn.XLOOKUP(Q12,Sheet2!$A$1:$A$7,Sheet2!$B$1:$B$7) -> 3 | T12: Considerably / Somewhat agree | U12: =_xlfn.XLOOKUP(T12,Sheet2!$A$1:$A$7,Sheet2!$B$1:$B$7) -> 5 | Y12: Very much / Agree | Z12: =_xlfn.XLOOKUP(Y12,Sheet2!$A$1:$A$7,Sheet2!$B$1:$B$7) -> 6 | AB12: Extremely / Strongly agree | AC12: =_xlfn.XLOOKUP(AB12,Sheet2!$A$1:$A$7,Sheet2!$B$1:$B$7) -> 7 | AE12: Extremely / Strongly agree | AF12: =_xlfn.XLOOKUP(AE12,Sheet2!$A$1:$A$7,Sheet2!$B$1:$B$7) -> 7 | AJ12: Very much / Agree | AK12: =_xlfn.XLOOKUP(AJ12,Sheet2!$A$1:$A$7,Sheet2!$B$1:$B$7) -> 6 | AM12: Slightly / Somewhat disagree | AN12: =_xlfn.XLOOKUP(AM12,Sheet2!$A$1:$A$7,Sheet2!$B$1:$B$7) -> 3 | AP12: Very slightly / Disagree | AQ12: =_xlfn.XLOOKUP(AP12,Sheet2!$A$1:$A$7,Sheet2!$B$1:$B$7) -> 2 | AS12: Moderately / Neutral | AT12: =_xlfn.XLOOKUP(AS12,Sheet2!$A$1:$A$7,Sheet2!$B$1:$B$7) -> 4 | AV12: Considerably / Somewhat agree | AW12: =_xlfn.XLOOKUP(AV12,Sheet2!$A$1:$A$7,Sheet2!$B$1:$B$7) -> 5 | AY12: Extremely / Strongly agree | AZ12: =_xlfn.XLOOKUP(AY12,Sheet2!$A$1:$A$7,Sheet2!$B$1:$B$7) -> 7 | BB12: Slightly / Somewhat disagree | BC12: =_xlfn.XLOOKUP(BB12,Sheet2!$A$1:$A$7,Sheet2!$B$1:$B$7) -> 3 | BE12: Considerably / Somewhat agree | BF12: =_xlfn.XLOOKUP(BE12,Sheet2!$A$1:$A$7,Sheet2!$B$1:$B$7) -> 5 | BH12: Slightly / Somewhat disagree | BI12: =_xlfn.XLOOKUP(BH12,Sheet2!$A$1:$A$7,Sheet2!$B$1:$B$7) -> 3 | BK12: Considerably / Somewhat agree | BL12: =_xlfn.XLOOKUP(BK12,Sheet2!$A$1:$A$7,Sheet2!$B$1:$B$7) -> 5 | BN12: Extremely / Strongly agree | BO12: =_xlfn.XLOOKUP(BN12,Sheet2!$A$1:$A$7,Sheet2!$B$1:$B$7) -> 7 | BQ12: Extremely / Strongly agree | BR12: =_xlfn.XLOOKUP(BQ12,Sheet2!$A$1:$A$7,Sheet2!$B$1:$B$7) -> 7 | BV12: Extremely / Strongly agree | BW12: =_xlfn.XLOOKUP(BV12,Sheet2!$A$1:$A$7,Sheet2!$B$1:$B$7) -> 7 | BY12: Extremely / Strongly agree | BZ12: =_xlfn.XLOOKUP(BY12,Sheet2!$A$1:$A$7,Sheet2!$B$1:$B$7) -> 7 | CD12: Extremely / Strongly agree | CE12: =_xlfn.XLOOKUP(CD12,Sheet2!$A$1:$A$7,Sheet2!$B$1:$B$7) -> 7 | CG12: Very much / Agree | CH12: =_xlfn.XLOOKUP(CG12,Sheet2!$A$1:$A$7,Sheet2!$B$1:$B$7) -> 6 | CJ12: Extremely / Strongly agree | CK12: =_xlfn.XLOOKUP(CJ12,Sheet2!$A$1:$A$7,Sheet2!$B$1:$B$7) -> 7 | CM12: Considerably / Somewhat agree | CN12: =_xlfn.XLOOKUP(CM12,Sheet2!$A$1:$A$7,Sheet2!$B$1:$B$7) -> 5 | CR12: Moderately / Neutral | CS12: =_xlfn.XLOOKUP(CR12,Sheet2!$A$1:$A$7,Sheet2!$B$1:$B$7) -> 4 | CU12: Considerably / Somewhat agree | CV12: =_xlfn.XLOOKUP(CU12,Sheet2!$A$1:$A$7,Sheet2!$B$1:$B$7) -> 5 | CX12: Moderately / Neutral | CY12: =_xlfn.XLOOKUP(CX12,Sheet2!$A$1:$A$7,Sheet2!$B$1:$B$7) -> 4 | DA12: Moderately / Neutral | DB12: =_xlfn.XLOOKUP(DA12,Sheet2!$A$1:$A$7,Sheet2!$B$1:$B$7) -> 4 | DF12: Considerably / Somewhat agree | DG12: =_xlfn.XLOOKUP(DF12,Sheet2!$A$1:$A$7,Sheet2!$B$1:$B$7) -> 5 | DI12: Considerably / Somewhat agree | DJ12: =_xlfn.XLOOKUP(DI12,Sheet2!$A$1:$A$7,Sheet2!$B$1:$B$7) -> 5
A13: 12 | B13: 46003.907 | C13: 46003.93 | D13: Congruent_6 | K13: Very much / Agree | L13: =_xlfn.XLOOKUP(K13,Sheet2!$A$1:$A$7,Sheet2!$B$1:$B$7) -> 6 | N13: Not at all / Strongly disagree | O13: =_xlfn.XLOOKUP(N13,Sheet2!$A$1:$A$7,Sheet2!$B$1:$B$7) -> 1 | Q13: Considerably / Somewhat agree | R13: =_xlfn.XLOOKUP(Q13,Sheet2!$A$1:$A$7,Sheet2!$B$1:$B$7) -> 5 | T13: Not at all / Strongly disagree | U13: =_xlfn.XLOOKUP(T13,Sheet2!$A$1:$A$7,Sheet2!$B$1:$B$7) -> 1 | Y13: Considerably / Somewhat agree | Z13: =_xlfn.XLOOKUP(Y13,Sheet2!$A$1:$A$7,Sheet2!$B$1:$B$7) -> 5 | AB13: Moderately / Neutral | AC13: =_xlfn.XLOOKUP(AB13,Sheet2!$A$1:$A$7,Sheet2!$B$1:$B$7) -> 4 | AE13: Considerably / Somewhat agree | AF13: =_xlfn.XLOOKUP(AE13,Sheet2!$A$1:$A$7,Sheet2!$B$1:$B$7) -> 5 | AJ13: Very slightly / Disagree | AK13: =_xlfn.XLOOKUP(AJ13,Sheet2!$A$1:$A$7,Sheet2!$B$1:$B$7) -> 2 | AM13: Considerably / Somewhat agree | AN13: =_xlfn.XLOOKUP(AM13,Sheet2!$A$1:$A$7,Sheet2!$B$1:$B$7) -> 5 | AP13: Slightly / Somewhat disagree | AQ13: =_xlfn.XLOOKUP(AP13,Sheet2!$A$1:$A$7,Sheet2!$B$1:$B$7) -> 3 | AS13: Very much / Agree | AT13: =_xlfn.XLOOKUP(AS13,Sheet2!$A$1:$A$7,Sheet2!$B$1:$B$7) -> 6 | AV13: Very much / Agree | AW13: =_xlfn.XLOOKUP(AV13,Sheet2!$A$1:$A$7,Sheet2!$B$1:$B$7) -> 6 | AY13: Very much / Agree | AZ13: =_xlfn.XLOOKUP(AY13,Sheet2!$A$1:$A$7,Sheet2!$B$1:$B$7) -> 6 | BB13: Very much / Agree | BC13: =_xlfn.XLOOKUP(BB13,Sheet2!$A$1:$A$7,Sheet2!$B$1:$B$7) -> 6 | BE13: Very slightly / Disagree | BF13: =_xlfn.XLOOKUP(BE13,Sheet2!$A$1:$A$7,Sheet2!$B$1:$B$7) -> 2 | BH13: Not at all / Strongly disagree | BI13: =_xlfn.XLOOKUP(BH13,Sheet2!$A$1:$A$7,Sheet2!$B$1:$B$7) -> 1 | BK13: Not at all / Strongly disagree | BL13: =_xlfn.XLOOKUP(BK13,Sheet2!$A$1:$A$7,Sheet2!$B$1:$B$7) -> 1 | BN13: Very much / Agree | BO13: =_xlfn.XLOOKUP(BN13,Sheet2!$A$1:$A$7,Sheet2!$B$1:$B$7) -> 6 | BQ13: Very much / Agree | BR13: =_xlfn.XLOOKUP(BQ13,Sheet2!$A$1:$A$7,Sheet2!$B$1:$B$7) -> 6 | BV13: Extremely / Strongly agree | BW13: =_xlfn.XLOOKUP(BV13,Sheet2!$A$1:$A$7,Sheet2!$B$1:$B$7) -> 7 | BY13: Very much / Agree | BZ13: =_xlfn.XLOOKUP(BY13,Sheet2!$A$1:$A$7,Sheet2!$B$1:$B$7) -> 6 | CD13: Very much / Agree | CE13: =_xlfn.XLOOKUP(CD13,Sheet2!$A$1:$A$7,Sheet2!$B$1:$B$7) -> 6 | CG13: Moderately / Neutral | CH13: =_xlfn.XLOOKUP(CG13,Sheet2!$A$1:$A$7,Sheet2!$B$1:$B$7) -> 4 | CJ13: Extremely / Strongly agree | CK13: =_xlfn.XLOOKUP(CJ13,Sheet2!$A$1:$A$7,Sheet2!$B$1:$B$7) -> 7 | CM13: Not at all / Strongly disagree | CN13: =_xlfn.XLOOKUP(CM13,Sheet2!$A$1:$A$7,Sheet2!$B$1:$B$7) -> 1 | CR13: Moderately / Neutral | CS13: =_xlfn.XLOOKUP(CR13,Sheet2!$A$1:$A$7,Sheet2!$B$1:$B$7) -> 4 | CU13: Not at all / Strongly disagree | CV13: =_xlfn.XLOOKUP(CU13,Sheet2!$A$1:$A$7,Sheet2!$B$1:$B$7) -> 1 | CX13: Moderately / Neutral | CY13: =_xlfn.XLOOKUP(CX13,Sheet2!$A$1:$A$7,Sheet2!$B$1:$B$7) -> 4 | DA13: Moderately / Neutral | DB13: =_xlfn.XLOOKUP(DA13,Sheet2!$A$1:$A$7,Sheet2!$B$1:$B$7) -> 4 | DF13: Very much / Agree | DG13: =_xlfn.XLOOKUP(DF13,Sheet2!$A$1:$A$7,Sheet2!$B$1:$B$7) -> 6 | DI13: Very much / Agree | DJ13: =_xlfn.XLOOKUP(DI13,Sheet2!$A$1:$A$7,Sheet2!$B$1:$B$7) -> 6
A14: 13 | B14: 46003.948 | C14: 46003.954 | D14: Incongruent_7 | K14: Moderately / Neutral | L14: =_xlfn.XLOOKUP(K14,Sheet2!$A$1:$A$7,Sheet2!$B$1:$B$7) -> 4 | N14: Very slightly / Disagree | O14: =_xlfn.XLOOKUP(N14,Sheet2!$A$1:$A$7,Sheet2!$B$1:$B$7) -> 2 | Q14: Moderately / Neutral | R14: =_xlfn.XLOOKUP(Q14,Sheet2!$A$1:$A$7,Sheet2!$B$1:$B$7) -> 4 | T14: Considerably / Somewhat agree | U14: =_xlfn.XLOOKUP(T14,Sheet2!$A$1:$A$7,Sheet2!$B$1:$B$7) -> 5 | Y14: Moderately / Neutral | Z14: =_xlfn.XLOOKUP(Y14,Sheet2!$A$1:$A$7,Sheet2!$B$1:$B$7) -> 4 | AB14: Very much / Agree | AC14: =_xlfn.XLOOKUP(AB14,Sheet2!$A$1:$A$7,Sheet2!$B$1:$B$7) -> 6 | AE14: Very much / Agree | AF14: =_xlfn.XLOOKUP(AE14,Sheet2!$A$1:$A$7,Sheet2!$B$1:$B$7) -> 6 | AJ14: Very much / Agree | AK14: =_xlfn.XLOOKUP(AJ14,Sheet2!$A$1:$A$7,Sheet2!$B$1:$B$7) -> 6 | AM14: Extremely / Strongly agree | AN14: =_xlfn.XLOOKUP(AM14,Sheet2!$A$1:$A$7,Sheet2!$B$1:$B$7) -> 7 | AP14: Considerably / Somewhat agree | AQ14: =_xlfn.XLOOKUP(AP14,Sheet2!$A$1:$A$7,Sheet2!$B$1:$B$7) -> 5 | AS14: Very much / Agree | AT14: =_xlfn.XLOOKUP(AS14,Sheet2!$A$1:$A$7,Sheet2!$B$1:$B$7) -> 6 | AV14: Considerably / Somewhat agree | AW14: =_xlfn.XLOOKUP(AV14,Sheet2!$A$1:$A$7,Sheet2!$B$1:$B$7) -> 5 | AY14: Extremely / Strongly agree | AZ14: =_xlfn.XLOOKUP(AY14,Sheet2!$A$1:$A$7,Sheet2!$B$1:$B$7) -> 7 | BB14: Moderately / Neutral | BC14: =_xlfn.XLOOKUP(BB14,Sheet2!$A$1:$A$7,Sheet2!$B$1:$B$7) -> 4 | BE14: Very much / Agree | BF14: =_xlfn.XLOOKUP(BE14,Sheet2!$A$1:$A$7,Sheet2!$B$1:$B$7) -> 6 | BH14: Slightly / Somewhat disagree | BI14: =_xlfn.XLOOKUP(BH14,Sheet2!$A$1:$A$7,Sheet2!$B$1:$B$7) -> 3 | BK14: Very much / Agree | BL14: =_xlfn.XLOOKUP(BK14,Sheet2!$A$1:$A$7,Sheet2!$B$1:$B$7) -> 6 | BN14: Considerably / Somewhat agree | BO14: =_xlfn.XLOOKUP(BN14,Sheet2!$A$1:$A$7,Sheet2!$B$1:$B$7) -> 5 | BQ14: Slightly / Somewhat disagree | BR14: =_xlfn.XLOOKUP(BQ14,Sheet2!$A$1:$A$7,Sheet2!$B$1:$B$7) -> 3 | BV14: Very much / Agree | BW14: =_xlfn.XLOOKUP(BV14,Sheet2!$A$1:$A$7,Sheet2!$B$1:$B$7) -> 6 | BY14: Very much / Agree | BZ14: =_xlfn.XLOOKUP(BY14,Sheet2!$A$1:$A$7,Sheet2!$B$1:$B$7) -> 6 | CD14: Considerably / Somewhat agree | CE14: =_xlfn.XLOOKUP(CD14,Sheet2!$A$1:$A$7,Sheet2!$B$1:$B$7) -> 5 | CG14: Very much / Agree | CH14: =_xlfn.XLOOKUP(CG14,Sheet2!$A$1:$A$7,Sheet2!$B$1:$B$7) -> 6 | CJ14: Slightly / Somewhat disagree | CK14: =_xlfn.XLOOKUP(CJ14,Sheet2!$A$1:$A$7,Sheet2!$B$1:$B$7) -> 3 | CM14: Moderately / Neutral | CN14: =_xlfn.XLOOKUP(CM14,Sheet2!$A$1:$A$7,Sheet2!$B$1:$B$7) -> 4 | CR14: Moderately / Neutral | CS14: =_xlfn.XLOOKUP(CR14,Sheet2!$A$1:$A$7,Sheet2!$B$1:$B$7) -> 4 | CU14: Slightly / Somewhat disagree | CV14: =_xlfn.XLOOKUP(CU14,Sheet2!$A$1:$A$7,Sheet2!$B$1:$B$7) -> 3 | CX14: Moderately / Neutral | CY14: =_xlfn.XLOOKUP(CX14,Sheet2!$A$1:$A$7,Sheet2!$B$1:$B$7) -> 4 | DA14: Considerably / Somewhat agree | DB14: =_xlfn.XLOOKUP(DA14,Sheet2!$A$1:$A$7,Sheet2!$B$1:$B$7) -> 5 | DF14: Considerably / Somewhat agree | DG14: =_xlfn.XLOOKUP(DF14,Sheet2!$A$1:$A$7,Sheet2!$B$1:$B$7) -> 5 | DI14: Considerably / Somewhat agree | DJ14: =_xlfn.XLOOKUP(DI14,Sheet2!$A$1:$A$7,Sheet2!$B$1:$B$7) -> 5

Sheet Sheet2
A1: Extremely / Strongly agree | B1: 7
A2: Very much / Agree | B2: 6
A3: Considerably / Somewhat agree | B3: 5
A4: Moderately / Neutral | B4: 4
A5: Slightly / Somewhat disagree | B5: 3
A6: Very slightly / Disagree | B6: 2
A7: Not at all / Strongly disagree | B7: 1

Sheet OfficeForms Table
A1: Question | B1: Attribute | C1: Congruent | D1: Incongruent
A2: Auditory perception | B2: How well could you identify sounds? | C2: 7 | D2: 6
A3: Auditory perception | B3: How well could you localize sounds? | C3: 5.5 | D3: 6
A4: Current Affective State | B4: I feel calm | C4: 5.5 | D4: 6
A5: Current Affective State | B5: I feel relaxed | C5: 5 | D5: 4
A6: Current Affective State | B6: I feel stressed | C6: 1.5 | D6: 2
A7: Current Affective State | B7: I feel tense | C7: 1.5 | D7: 2
A8: Immersive Tendency | B8: I am good at blocking out external distractions when focused. | C8: 5 | D8: 6
A9: Immersive Tendency | B9: I easily become deeply involved in movies or virtual experiences. | C9: 4.5 | D9: 5
A10: Immersive Tendency | B10: I often lose track of time when engaged in an activity. | C10: 4 | D10: 6
A11: Navigation Experience | B11: How confident did you feel about where you were in the environment at any moment? | C11: 5.5 | D11: 5
A12: Navigation Experience | B12: How easy was it to find your way through the environment? | C12: 5.5 | D12: 5
A13: Navigation Experience | B13: To what extent did sounds distract you from navigation? | C13: 1 | D13: 2
... A32: Sense of presence and immersion | B32: Were you involved in the experience to the extent that you lost track of time? | C32: 4.5 | D32: 5

Sheet OfficeForms Table Clean
A1: Id | B1: Start time | C1: Completion time | D1: Email | E1: Current Affective State . I feel calm | F1: Points - Current Affective State . I feel calm | G1: Current Affective State . I feel tense | H1: Points - Current Affective State . I feel tense | I1: Current Affective State . I feel relaxed | J1: Points - Current Affective State . I feel relaxed | K1: Current Affective State . I feel stressed | L1: Points - Current Affective State . I feel stressed | M1: Immersive Tendency. I easily become deeply involved in movies or virtual experiences. | N1: Points - Immersive Tendency. I easily become deeply involved in movies or virtual experiences. | O1: Immersive Tendency. I am good at blocking out external distractions when focused. | P1: Points - Immersive Tendency. I am good at blocking out external distractions when focused. | Q1: Immersive Tendency. I often lose track of time when engaged in an activity. | R1: Points - Immersive Tendency. I often lose track of time when engaged in an activity. | S1: Sense of presence and immersion.How much were you able to control the events? | T1: Points - Sense of presence and immersion.How much were you able to control the events? | U1: Sense of presence and immersion.How responsive was the environment to actions that you initiated? | V1: Points - Sense of presence and immersion.How responsive was the environment to actions that you initiated? | W1: Sense of presence and immersion.How natural did your interactions with the environment seem? | X1: Points - Sense of presence and immersion.How natural did your interactions with the environment seem? | Y1: Sense of presence and immersion. How completely were all of your senses engaged? | Z1: Points - Sense of presence and immersion. How completely were all of your senses engaged? | AA1: Sense of presence and immersion. How much did the visual aspects of the environment involve you? | AB1: Points - Sense of presence and immersion. How much did the visual aspects of the environment involve you? | AC1: Sense of presence and immersion. How much did the auditory aspects of the environment involve you? | AD1: Points - Sense of presence and immersion. How much did the auditory aspects of the environment involve you? | AE1: Sense of presence and immersion. How compelling was your sense of objects moving through space? | AF1: Points - Sense of presence and immersion. How compelling was your sense of objects moving through space? | AG1: Sense of presence and immersion. How inconsistent or disconnected was the information coming from your various senses? | AH1: Points - Sense of presence and immersion. How inconsistent or disconnected was the information coming from your various senses? | AI1: Sense of presence and immersion. How much did your experiences in the virtual environment seem consistent with your real-world experiences? | AJ1: Points - Sense of presence and immersion. How much did your experiences in the virtual environment seem consistent with your real-world experiences? | AK1: Sense of presence and immersion. How compelling was your sense of moving around inside the virtual environment? | AL1: Points - Sense of presence and immersion. How compelling was your sense of moving around inside the virtual environment? | AM1: Sense of presence and immersion. How involved were you in the virtual environment experience? | AN1: Points - Sense of presence and immersion. How involved were you in the virtual environment experience? | AO1: Sense of presence and immersion. Were you involved in the experience to the extent that you lost track of time? | AP1: Points - Sense of presence and immersion. Were you involved in the experience to the extent that you lost track of time? | AQ1: Auditory perception. How well could you identify sounds? | AR1: Points - Auditory perception. How well could you identify sounds? | AS1: Auditory perception. How well could you localize sounds? | AT1: Points - Auditory perception. How well could you localize sounds? | AU1: Navigation Experience. How easy was it to find your way through the environment? | AV1: Points - Navigation Experience. How easy was it to find your way through the environment? | AW1: Navigation Experience. How confident did you feel about where you were in the environment at any moment? | AX1: Points - Navigation Experience. How confident did you feel about where you were in the environment at any moment? | AY1: Navigation Experience. To what extent did sounds help you decide where to go next? | AZ1: Points - Navigation Experience. To what extent did sounds help you decide where to go next? | BA1: Navigation Experience. To what extent did sounds distract you from navigation? | BB1: Points - Navigation Experience. To what extent did sounds distract you from navigation? | BC1: Post-Experience Affective State . I feel calm | BD1: Points - Post-Experience Affective State . I feel calm | BE1: Post-Experience Affective State . I feel tense | BF1: Points - Post-Experience Affective State . I feel tense | BG1: Post-Experience Affective State . I feel relaxed | BH1: Points - Post-Experience Affective State . I feel relaxed | BI1: Post-Experience Affective State . I feel stressed | BJ1: Points - Post-Experience Affective State . I feel stressed | BK1: Physical Comfort. I felt disoriented during or after the experience. | BL1: Points - Physical Comfort. I felt disoriented during or after the experience. | BM1: Physical Comfort. I felt physically uncomfortable during the experience. | BN1: Points - Physical Comfort. I felt physically uncomfortable during the experience.
A2: 1 | B2: 46001.815 | C2: 46001.846 | D2: Congruent_1_1.2 | E2: Considerably / Somewhat agree | F2: 5 | G2: Not at all / Strongly disagree | H2: 1 | I2: Moderately / Neutral | J2: 4 | K2: Not at all / Strongly disagree | L2: 1 | M2: Very slightly / Disagree | N2: 2 | O2: Very much / Agree | P2: 6 | Q2: Slightly / Somewhat disagree | R2: 3 | S2: Very much / Agree | T2: 6 | U2: Considerably / Somewhat agree | V2: 5 | W2: Considerably / Somewhat agree | X2: 5 | Y2: Moderately / Neutral | Z2: 4 | AA2: Extremely / Strongly agree | AB2: 7 | AC2: Moderately / Neutral | AD2: 4 | AE2: Moderately / Neutral | AF2: 4 | AG2: Very much / Agree | AH2: 6 | AI2: Extremely / Strongly agree | AJ2: 7 | AK2: Slightly / Somewhat disagree | AL2: 3 | AM2: Very slightly / Disagree | AN2: 2 | AO2: Slightly / Somewhat disagree | AP2: 3 | AQ2: Considerably / Somewhat agree | AR2: 5 | AS2: Slightly / Somewhat disagree | AT2: 3 | AU2: Slightly / Somewhat disagree | AV2: 3 | AW2: Very much / Agree | AX2: 6 | AY2: Considerably / Somewhat agree | AZ2: 5 | BA2: Very much / Agree | BB2: 6 | BC2: Not at all / Strongly disagree | BD2: 1 | BE2: Very much / Agree | BF2: 6 | BG2: Not at all / Strongly disagree | BH2: 1 | BI2: Extremely / Strongly agree | BJ2: 7 | BK2: Very much / Agree | BL2: 6 | BM2: Extremely / Strongly agree | BN2: 7
A3: 2 | B3: 46001.84 | C3: 46001.853 | D3: Incongruent_1 | E3: Very much / Agree | F3: 6 | G3: Not at all / Strongly disagree | H3: 1 | I3: Very much / Agree | J3: 6 | K3: Very slightly / Disagree | L3: 2 | M3: Moderately / Neutral | N3: 4 | O3: Very much / Agree | P3: 6 | Q3: Slightly / Somewhat disagree | R3: 3 | S3: Slightly / Somewhat disagree | T3: 3 | U3: Very slightly / Disagree | V3: 2 | W3: Slightly / Somewhat disagree | X3: 3 | Y3: Very much / Agree | Z3: 6 | AA3: Moderately / Neutral | AB3: 4 | AC3: Very much / Agree | AD3: 6 | AE3: Moderately / Neutral | AF3: 4 | AG3: Very slightly / Disagree | AH3: 2 | AI3: Slightly / Somewhat disagree | AJ3: 3 | AK3: Moderately / Neutral | AL3: 4 | AM3: Very much / Agree | AN3: 6 | AO3: Very much / Agree | AP3: 6 | AQ3: Very much / Agree | AR3: 6 | AS3: Very much / Agree | AT3: 6 | AU3: Slightly / Somewhat disagree | AV3: 3 | AW3: Slightly / Somewhat disagree | AX3: 3 | AY3: Very much / Agree | AZ3: 6 | BA3: Very slightly / Disagree | BB3: 2 | BC3: Very slightly / Disagree | BD3: 2 | BE3: Very slightly / Disagree | BF3: 2 | BG3: Very slightly / Disagree | BH3: 2 | BI3: Very much / Agree | BJ3: 6 | BK3: Not at all / Strongly disagree | BL3: 1 | BM3: Considerably / Somewhat agree | BN3: 5
